<?xml version="1.0" encoding="UTF-8"?>
<testng-results ignored="0" total="3" passed="1" failed="2" skipped="0">
  <reporter-output>
  </reporter-output>
  <suite started-at="2025-05-22T17:37:05 IST" name="Login Test Suite" finished-at="2025-05-22T17:37:42 IST" duration-ms="36464">
    <groups>
    </groups>
    <test started-at="2025-05-22T17:37:05 IST" name="Login Test Suite" finished-at="2025-05-22T17:37:42 IST" duration-ms="36464">
      <class name="testClasses.TC_login_WrongPassword">
        <test-method is-config="true" signature="setup()[pri:0, instance:testClasses.TC_login_WrongPassword@436813f3]" started-at="2025-05-22T17:37:27 IST" name="setup" finished-at="2025-05-22T17:37:31 IST" duration-ms="4140" status="PASS">
          <reporter-output>
          </reporter-output>
        </test-method> <!-- setup -->
        <test-method signature="login()[pri:0, instance:testClasses.TC_login_WrongPassword@436813f3]" started-at="2025-05-22T17:37:31 IST" name="login" finished-at="2025-05-22T17:37:41 IST" duration-ms="10225" status="FAIL">
          <exception class="java.lang.AssertionError">
            <message>
              <![CDATA[Login succeeded or unexpected behavior: Your password is invalid!]]>
            </message>
            <full-stacktrace>
              <![CDATA[java.lang.AssertionError: Login succeeded or unexpected behavior: Your password is invalid!
at org.testng.Assert.fail(Assert.java:111)
at testClasses.TC_login_WrongPassword.login(TC_login_WrongPassword.java:43)
at java.base/jdk.internal.reflect.DirectMethodHandleAccessor.invoke(DirectMethodHandleAccessor.java:103)
at java.base/java.lang.reflect.Method.invoke(Method.java:580)
at org.testng.internal.invokers.MethodInvocationHelper.invokeMethod(MethodInvocationHelper.java:139)
at org.testng.internal.invokers.TestInvoker.invokeMethod(TestInvoker.java:664)
at org.testng.internal.invokers.TestInvoker.invokeTestMethod(TestInvoker.java:228)
at org.testng.internal.invokers.MethodRunner.runInSequence(MethodRunner.java:63)
at org.testng.internal.invokers.TestInvoker$MethodInvocationAgent.invoke(TestInvoker.java:961)
at org.testng.internal.invokers.TestInvoker.invokeTestMethods(TestInvoker.java:201)
at org.testng.internal.invokers.TestMethodWorker.invokeTestMethods(TestMethodWorker.java:148)
at org.testng.internal.invokers.TestMethodWorker.run(TestMethodWorker.java:128)
at java.base/java.util.ArrayList.forEach(ArrayList.java:1597)
at org.testng.TestRunner.privateRun(TestRunner.java:819)
at org.testng.TestRunner.run(TestRunner.java:619)
at org.testng.SuiteRunner.runTest(SuiteRunner.java:443)
at org.testng.SuiteRunner.runSequentially(SuiteRunner.java:437)
at org.testng.SuiteRunner.privateRun(SuiteRunner.java:397)
at org.testng.SuiteRunner.run(SuiteRunner.java:336)
at org.testng.SuiteRunnerWorker.runSuite(SuiteRunnerWorker.java:52)
at org.testng.SuiteRunnerWorker.run(SuiteRunnerWorker.java:95)
at org.testng.TestNG.runSuitesSequentially(TestNG.java:1301)
at org.testng.TestNG.runSuitesLocally(TestNG.java:1228)
at org.testng.TestNG.runSuites(TestNG.java:1134)
at org.testng.TestNG.run(TestNG.java:1101)
at org.apache.maven.surefire.testng.TestNGExecutor.run(TestNGExecutor.java:308)
at org.apache.maven.surefire.testng.TestNGXmlTestSuite.execute(TestNGXmlTestSuite.java:71)
at org.apache.maven.surefire.testng.TestNGProvider.invoke(TestNGProvider.java:113)
at org.apache.maven.surefire.booter.ForkedBooter.runSuitesInProcess(ForkedBooter.java:385)
at org.apache.maven.surefire.booter.ForkedBooter.execute(ForkedBooter.java:162)
at org.apache.maven.surefire.booter.ForkedBooter.run(ForkedBooter.java:507)
at org.apache.maven.surefire.booter.ForkedBooter.main(ForkedBooter.java:495)
]]>
            </full-stacktrace>
          </exception> <!-- java.lang.AssertionError -->
          <reporter-output>
          </reporter-output>
        </test-method> <!-- login -->
        <test-method is-config="true" signature="tearDown()[pri:0, instance:testClasses.TC_login_WrongPassword@436813f3]" started-at="2025-05-22T17:37:42 IST" name="tearDown" finished-at="2025-05-22T17:37:42 IST" duration-ms="119" status="PASS">
          <reporter-output>
          </reporter-output>
        </test-method> <!-- tearDown -->
      </class> <!-- testClasses.TC_login_WrongPassword -->
      <class name="testClasses.TC_001_Login">
        <test-method is-config="true" signature="setup()[pri:0, instance:testClasses.TC_001_Login@7e07db1f]" started-at="2025-05-22T17:37:05 IST" name="setup" finished-at="2025-05-22T17:37:10 IST" duration-ms="4877" status="PASS">
          <reporter-output>
          </reporter-output>
        </test-method> <!-- setup -->
        <test-method signature="login()[pri:0, instance:testClasses.TC_001_Login@7e07db1f]" started-at="2025-05-22T17:37:10 IST" name="login" finished-at="2025-05-22T17:37:12 IST" duration-ms="1700" status="PASS">
          <reporter-output>
          </reporter-output>
        </test-method> <!-- login -->
        <test-method is-config="true" signature="tearDown()[pri:0, instance:testClasses.TC_001_Login@7e07db1f]" started-at="2025-05-22T17:37:12 IST" name="tearDown" finished-at="2025-05-22T17:37:12 IST" duration-ms="92" status="PASS">
          <reporter-output>
          </reporter-output>
        </test-method> <!-- tearDown -->
      </class> <!-- testClasses.TC_001_Login -->
      <class name="testClasses.TC_login_WrongUserName">
        <test-method is-config="true" signature="setup()[pri:0, instance:testClasses.TC_login_WrongUserName@8f4ea7c]" started-at="2025-05-22T17:37:12 IST" name="setup" finished-at="2025-05-22T17:37:17 IST" duration-ms="4304" status="PASS">
          <reporter-output>
          </reporter-output>
        </test-method> <!-- setup -->
        <test-method signature="login()[pri:0, instance:testClasses.TC_login_WrongUserName@8f4ea7c]" started-at="2025-05-22T17:37:17 IST" name="login" finished-at="2025-05-22T17:37:27 IST" duration-ms="10250" status="FAIL">
          <exception class="java.lang.AssertionError">
            <message>
              <![CDATA[Login succeeded or unexpected behavior: ]]>
            </message>
            <full-stacktrace>
              <![CDATA[java.lang.AssertionError: Login succeeded or unexpected behavior: 
at org.testng.Assert.fail(Assert.java:111)
at testClasses.TC_login_WrongUserName.login(TC_login_WrongUserName.java:40)
at java.base/jdk.internal.reflect.DirectMethodHandleAccessor.invoke(DirectMethodHandleAccessor.java:103)
at java.base/java.lang.reflect.Method.invoke(Method.java:580)
at org.testng.internal.invokers.MethodInvocationHelper.invokeMethod(MethodInvocationHelper.java:139)
at org.testng.internal.invokers.TestInvoker.invokeMethod(TestInvoker.java:664)
at org.testng.internal.invokers.TestInvoker.invokeTestMethod(TestInvoker.java:228)
at org.testng.internal.invokers.MethodRunner.runInSequence(MethodRunner.java:63)
at org.testng.internal.invokers.TestInvoker$MethodInvocationAgent.invoke(TestInvoker.java:961)
at org.testng.internal.invokers.TestInvoker.invokeTestMethods(TestInvoker.java:201)
at org.testng.internal.invokers.TestMethodWorker.invokeTestMethods(TestMethodWorker.java:148)
at org.testng.internal.invokers.TestMethodWorker.run(TestMethodWorker.java:128)
at java.base/java.util.ArrayList.forEach(ArrayList.java:1597)
at org.testng.TestRunner.privateRun(TestRunner.java:819)
at org.testng.TestRunner.run(TestRunner.java:619)
at org.testng.SuiteRunner.runTest(SuiteRunner.java:443)
at org.testng.SuiteRunner.runSequentially(SuiteRunner.java:437)
at org.testng.SuiteRunner.privateRun(SuiteRunner.java:397)
at org.testng.SuiteRunner.run(SuiteRunner.java:336)
at org.testng.SuiteRunnerWorker.runSuite(SuiteRunnerWorker.java:52)
at org.testng.SuiteRunnerWorker.run(SuiteRunnerWorker.java:95)
at org.testng.TestNG.runSuitesSequentially(TestNG.java:1301)
at org.testng.TestNG.runSuitesLocally(TestNG.java:1228)
at org.testng.TestNG.runSuites(TestNG.java:1134)
at org.testng.TestNG.run(TestNG.java:1101)
at org.apache.maven.surefire.testng.TestNGExecutor.run(TestNGExecutor.java:308)
at org.apache.maven.surefire.testng.TestNGXmlTestSuite.execute(TestNGXmlTestSuite.java:71)
at org.apache.maven.surefire.testng.TestNGProvider.invoke(TestNGProvider.java:113)
at org.apache.maven.surefire.booter.ForkedBooter.runSuitesInProcess(ForkedBooter.java:385)
at org.apache.maven.surefire.booter.ForkedBooter.execute(ForkedBooter.java:162)
at org.apache.maven.surefire.booter.ForkedBooter.run(ForkedBooter.java:507)
at org.apache.maven.surefire.booter.ForkedBooter.main(ForkedBooter.java:495)
]]>
            </full-stacktrace>
          </exception> <!-- java.lang.AssertionError -->
          <reporter-output>
          </reporter-output>
        </test-method> <!-- login -->
        <test-method is-config="true" signature="tearDown()[pri:0, instance:testClasses.TC_login_WrongUserName@8f4ea7c]" started-at="2025-05-22T17:37:27 IST" name="tearDown" finished-at="2025-05-22T17:37:27 IST" duration-ms="93" status="PASS">
          <reporter-output>
          </reporter-output>
        </test-method> <!-- tearDown -->
      </class> <!-- testClasses.TC_login_WrongUserName -->
    </test> <!-- Login Test Suite -->
  </suite> <!-- Login Test Suite -->
</testng-results>
